<?xml version="1.0" encoding="UTF-8"?>
<sdf version='1.6'>
  <model name='baby_k'>
    <pose>0 0 0 0 0 0</pose>
    <self_collide>false</self_collide>
    <static>false</static>
    <link name='base_link'>
      <inertial>
        <mass>2.467</mass>
        <inertia>
          <ixx>0.008</ixx>
          <ixy>0</ixy>
          <ixz>0</ixz>
          <iyy>0.103</iyy>
          <iyz>0</iyz>
          <izz>0.108</izz>
        </inertia>
      </inertial>
      <gravity>true</gravity>
      <velocity_decay/>
      <visual name="base_link_visual">
        <pose>0 0 0 0 0 0</pose>
        <geometry>
          <box>
            <size>0.80 0.18 0.1</size>
          </box>
        </geometry>
        <material>
          <script>
            <name>Gazebo/DarkGrey</name>
            <uri>file://media/materials/scripts/gazebo.material</uri>
          </script>
        </material>
      </visual>
      <collision name="base_link_collision_0">
        <pose>0 0 0 0 0 0</pose>
        <geometry>
          <box>
            <size>0.8 0.18 0.3</size>
          </box>
        </geometry>
        <surface>
          <contact>
            <ode>
              <min_depth>0.001</min_depth>
              <max_vel>0</max_vel>
            </ode>
          </contact>
          <friction>
            <ode/>
          </friction>
        </surface>
      </collision>
      <visual name="arm_left_front">
        <pose>0.25 0.16 0 1.57 0 0</pose>
        <geometry>
          <cylinder>
            <radius>0.015</radius>
            <length>0.32</length>
          </cylinder>
        </geometry>
        <material>
          <script>
            <name>Gazebo/DarkGrey</name>
            <uri>file://media/materials/scripts/gazebo.material</uri>
          </script>
        </material>
      </visual>
      <collision name="arm_left_front_collision_0">
        <pose>0.25 0.16 0 1.57 0 0</pose>
        <geometry>
          <cylinder>
            <radius>0.015</radius>
            <length>0.32</length>
          </cylinder>
        </geometry>
        <surface>
          <contact>
            <ode>
              <min_depth>0.001</min_depth>
              <max_vel>0</max_vel>
            </ode>
          </contact>
          <friction>
            <ode/>
          </friction>
        </surface>
      </collision>
      <visual name="arm_right_front">
        <pose>0.25 -0.16 0 1.57 0 0</pose>
        <geometry>
          <cylinder>
            <radius>0.015</radius>
            <length>0.32</length>
          </cylinder>
        </geometry>
        <material>
          <script>
            <name>Gazebo/DarkGrey</name>
            <uri>file://media/materials/scripts/gazebo.material</uri>
          </script>
        </material>
      </visual>
      <collision name="arm_right_front_collision_0">
        <pose>0.25 -0.16 0 1.57 0 0</pose>
        <geometry>
          <cylinder>
            <radius>0.015</radius>
            <length>0.32</length>
          </cylinder>
        </geometry>
        <surface>
          <contact>
            <ode>
              <min_depth>0.001</min_depth>
              <max_vel>0</max_vel>
            </ode>
          </contact>
          <friction>
            <ode/>
          </friction>
        </surface>
      </collision>
      <visual name="arm_left_rear">
        <pose>-0.25 0.16 0 1.57 0 0</pose>
        <geometry>
          <cylinder>
            <radius>0.015</radius>
            <length>0.32</length>
          </cylinder>
        </geometry>
        <material>
          <script>
            <name>Gazebo/DarkGrey</name>
            <uri>file://media/materials/scripts/gazebo.material</uri>
          </script>
        </material>
      </visual>
      <collision name="arm_left_rear_collision_0">
        <pose>-0.25 0.16 0 1.57 0 0</pose>
        <geometry>
          <cylinder>
            <radius>0.015</radius>
            <length>0.32</length>
          </cylinder>
        </geometry>
        <surface>
          <contact>
            <ode>
              <min_depth>0.001</min_depth>
              <max_vel>0</max_vel>
            </ode>
          </contact>
          <friction>
            <ode/>
          </friction>
        </surface>
      </collision>
      <visual name="arm_right_rear">
        <pose>-0.25 -0.16 0 1.57 0 0</pose>
        <geometry>
          <cylinder>
            <radius>0.015</radius>
            <length>0.32</length>
          </cylinder>
        </geometry>
        <material>
          <script>
            <name>Gazebo/DarkGrey</name>
            <uri>file://media/materials/scripts/gazebo.material</uri>
          </script>
        </material>
      </visual>
      <collision name="arm_right_rear_collision_0">
        <pose>-0.25 -0.16 0 1.57 0 0</pose>
        <geometry>
          <cylinder>
            <radius>0.015</radius>
            <length>0.32</length>
          </cylinder>
        </geometry>
        <surface>
          <contact>
            <ode>
              <min_depth>0.001</min_depth>
              <max_vel>0</max_vel>
            </ode>
          </contact>
          <friction>
            <ode/>
          </friction>
        </surface>
      </collision>
    </link>

    <link name='/imu_link'>
      <pose>0 0 0 0 0 0</pose>
      <inertial>
        <pose>0 0 0 0 0 0</pose>
        <mass>0.015</mass>
        <inertia>
          <ixx>1e-05</ixx>
          <ixy>0</ixy>
          <ixz>0</ixz>
          <iyy>1e-05</iyy>
          <iyz>0</iyz>
          <izz>1e-05</izz>
        </inertia>
      </inertial>
    </link>
    <include>
      <uri>model://imu</uri>
      <pose>0 0 0 0 0 0</pose>
      <name>imu</name>
    </include>
    <joint name='imu_joint' type='revolute'>
      <child>imu::link</child>
      <parent>base_link</parent>
      <axis>
        <xyz>1 0 0</xyz>
        <limit>
          <lower>0</lower>
          <upper>0</upper>
          <effort>0</effort>
          <velocity>0</velocity>
        </limit>
        <dynamics>
          <spring_reference>0</spring_reference>
          <spring_stiffness>0</spring_stiffness>
        </dynamics>
        <use_parent_model_frame>1</use_parent_model_frame>
      </axis>
    </joint>

    <link name="base_left_front">
      <pose>0.25 0.32 0 0 0 0</pose>
      <inertial>
        <mass>0.028</mass>
        <inertia>
          <ixx>0.001</ixx>
          <ixy>0</ixy>
          <ixz>0</ixz>
          <iyy>0.001</iyy>
          <iyz>0</iyz>
          <izz>0.001</izz>
        </inertia>
      </inertial>
      <visual name="base_left_front_visual">
        <geometry>
          <box>
            <size>0.04 0.04 0.05</size>
          </box>
        </geometry>
        <material>
          <script>
            <name>Gazebo/DarkGrey</name>
            <uri>file://media/materials/scripts/gazebo.material</uri>
          </script>
        </material>
      </visual>
      <collision name="base_left_front_collision">
        <pose>0 0 0 0 0 0</pose>
        <geometry>
          <box>
            <size>0.04 0.04 0.05</size>
          </box>
        </geometry>
        <surface>
          <contact>
            <ode>
              <min_depth>0.001</min_depth>
              <max_vel>0</max_vel>
            </ode>
          </contact>
          <friction>
            <ode/>
          </friction>
        </surface>
      </collision>
    </link>
    <joint name="base_left_front_joint" type="revolute">
      <parent>base_link</parent>
      <child>base_left_front</child>
      <axis>
        <xyz>0 1 0</xyz>
        <limit>
          <lower>-1e+16</lower>
          <upper>1e+16</upper>
        </limit>
        <dynamics>
          <spring_reference>0</spring_reference>
          <spring_stiffness>0</spring_stiffness>
        </dynamics>
      </axis>
    </joint>
    <link name="base_right_front">
      <pose>0.25 -0.32 0 0 0 0</pose>
      <inertial>
        <mass>0.028</mass>
        <inertia>
          <ixx>0.001</ixx>
          <ixy>0</ixy>
          <ixz>0</ixz>
          <iyy>0.001</iyy>
          <iyz>0</iyz>
          <izz>0.001</izz>
        </inertia>
      </inertial>
      <visual name="base_left_front_visual">
        <geometry>
          <box>
            <size>0.04 0.04 0.05</size>
          </box>
        </geometry>
        <material>
          <script>
            <name>Gazebo/DarkGrey</name>
            <uri>file://media/materials/scripts/gazebo.material</uri>
          </script>
        </material>
      </visual>
      <collision name="base_right_front_collision">
        <pose>0 0 0 0 0 0</pose>
        <geometry>
          <box>
            <size>0.04 0.04 0.05</size>
          </box>
        </geometry>
        <surface>
          <contact>
            <ode>
              <min_depth>0.001</min_depth>
              <max_vel>0</max_vel>
            </ode>
          </contact>
          <friction>
            <ode/>
          </friction>
        </surface>
      </collision>
    </link>
    <joint name="base_right_front_joint" type="revolute">
      <parent>base_link</parent>
      <child>base_right_front</child>
      <axis>
        <xyz>0 1 0</xyz>
        <limit>
          <lower>-1e+16</lower>
          <upper>1e+16</upper>
        </limit>
        <dynamics>
          <spring_reference>0</spring_reference>
          <spring_stiffness>0</spring_stiffness>
        </dynamics>
      </axis>
    </joint>
    <!-- ARMS REAR -->
    <link name="base_left_rear">
      <pose>-0.25 0.32 0 0 0 0</pose>
      <inertial>
        <mass>0.028</mass>
        <inertia>
          <ixx>0.001</ixx>
          <ixy>0</ixy>
          <ixz>0</ixz>
          <iyy>0.001</iyy>
          <iyz>0</iyz>
          <izz>0.001</izz>
        </inertia>
      </inertial>
      <visual name="base_left_rear_visual">
        <geometry>
          <box>
            <size>0.04 0.04 0.05</size>
          </box>
        </geometry>
        <material>
          <script>
            <name>Gazebo/DarkGrey</name>
            <uri>file://media/materials/scripts/gazebo.material</uri>
          </script>
        </material>
      </visual>
      <collision name="base_left_rear_collision">
        <pose>0 0 0 0 0 0</pose>
        <geometry>
          <box>
            <size>0.04 0.04 0.05</size>
          </box>
        </geometry>
        <surface>
          <contact>
            <ode>
              <min_depth>0.001</min_depth>
              <max_vel>0</max_vel>
            </ode>
          </contact>
          <friction>
            <ode/>
          </friction>
        </surface>
      </collision>
    </link>
    <joint name="base_left_rear_joint" type="revolute">
      <parent>base_link</parent>
      <child>base_left_rear</child>
      <axis>
        <xyz>0 1 0</xyz>
        <limit>
          <lower>-1e+16</lower>
          <upper>1e+16</upper>
        </limit>
        <dynamics>
          <spring_reference>0</spring_reference>
          <spring_stiffness>0</spring_stiffness>
        </dynamics>
      </axis>
    </joint>
    <link name="base_right_rear">
      <pose>-0.25 -0.32 0 0 0 0</pose>
      <inertial>
        <mass>0.028</mass>
        <inertia>
          <ixx>0.001</ixx>
          <ixy>0</ixy>
          <ixz>0</ixz>
          <iyy>0.001</iyy>
          <iyz>0</iyz>
          <izz>0.001</izz>
        </inertia>
      </inertial>
      <visual name="base_right_rear_visual">
        <geometry>
          <box>
            <size>0.04 0.04 0.05</size>
          </box>
        </geometry>
        <material>
          <script>
            <name>Gazebo/DarkGrey</name>
            <uri>file://media/materials/scripts/gazebo.material</uri>
          </script>
        </material>
      </visual>
      <collision name="base_right_rear_collision">
        <pose>0 0 0 0 0 0</pose>
        <geometry>
          <box>
            <size>0.04 0.04 0.05</size>
          </box>
        </geometry>
        <surface>
          <contact>
            <ode>
              <min_depth>0.001</min_depth>
              <max_vel>0</max_vel>
            </ode>
          </contact>
          <friction>
            <ode/>
          </friction>
        </surface>
      </collision>
    </link>
    <joint name="base_right_rear_joint" type="revolute">
      <parent>base_link</parent>
      <child>base_right_rear</child>
      <axis>
        <xyz>0 1 0</xyz>
        <limit>
          <lower>-1e+16</lower>
          <upper>1e+16</upper>
        </limit>
        <dynamics>
          <spring_reference>0</spring_reference>
          <spring_stiffness>0</spring_stiffness>
        </dynamics>
      </axis>
    </joint>
  <!-- PROPELLERS -->
    <link name="prop_left_front_top">
      <pose>0.25 0.32 0.03 0 0 0</pose>
      <inertial>
        <mass>0.151</mass>
        <inertia>
          <ixx>1.676e-4</ixx>
          <ixy>0</ixy>
          <ixz>0</ixz>
          <iyy>1.663e-4</iyy>
          <iyz>0</iyz>
          <izz>2.620e-4</izz>
        </inertia>
      </inertial>
      <visual name="prop_left_front_top_visual">
        <geometry>
          <box>
            <size>0.03 0.25 0.005</size>
          </box>
        </geometry>
        <material>
          <script>
            <name>Gazebo/DarkGrey</name>
            <uri>file://media/materials/scripts/gazebo.material</uri>
          </script>
        </material>
      </visual>
      <collision name="prop_left_front_top_collision">
        <pose>0 0 0 0 0 0</pose>
        <geometry>
          <box>
            <size>0.03 0.25 0.005</size>
          </box>
        </geometry>
        <surface>
          <contact>
            <ode>
              <min_depth>0.001</min_depth>
              <max_vel>0</max_vel>
            </ode>
          </contact>
          <friction>
            <ode/>
          </friction>
        </surface>
      </collision>
    </link>
    <joint name="prop_left_front_top_joint" type="revolute">
      <parent>base_left_front</parent>
      <child>prop_left_front_top</child>
      <axis>
        <xyz>0 0 1</xyz>
        <limit>
          <lower>-1e+16</lower>
          <upper>1e+16</upper>
        </limit>
        <dynamics>
          <spring_reference>0</spring_reference>
          <spring_stiffness>0</spring_stiffness>
        </dynamics>
      </axis>
    </joint>
    <link name="prop_left_front_bottom">
      <pose>0.25 0.32 -0.03 0 0 0</pose>
      <inertial>
        <mass>0.151</mass>
        <inertia>
          <ixx>1.676e-4</ixx>
          <ixy>0</ixy>
          <ixz>0</ixz>
          <iyy>1.663e-4</iyy>
          <iyz>0</iyz>
          <izz>2.620e-4</izz>
        </inertia>
      </inertial>
      <visual name="base_left_front_bottom_visual">
        <geometry>
          <box>
            <size>0.03 0.25 0.005</size>
          </box>
        </geometry>
        <material>
          <script>
            <name>Gazebo/DarkGrey</name>
            <uri>file://media/materials/scripts/gazebo.material</uri>
          </script>
        </material>
      </visual>
      <collision name="prop_left_front_bottom_collision">
        <pose>0 0 0 0 0 0</pose>
        <geometry>
          <box>
            <size>0.03 0.25 0.005</size>
          </box>
        </geometry>
        <surface>
          <contact>
            <ode>
              <min_depth>0.001</min_depth>
              <max_vel>0</max_vel>
            </ode>
          </contact>
          <friction>
            <ode/>
          </friction>
        </surface>
      </collision>
    </link>
    <joint name="prop_left_front_bottom_joint" type="revolute">
      <parent>base_left_front</parent>
      <child>prop_left_front_bottom</child>
      <axis>
        <xyz>0 0 1</xyz>
        <limit>
          <lower>-1e+16</lower>
          <upper>1e+16</upper>
        </limit>
        <dynamics>
          <spring_reference>0</spring_reference>
          <spring_stiffness>0</spring_stiffness>
        </dynamics>
      </axis>
    </joint>
    <!-- RIGHT -->
    <link name="prop_right_front_top">
      <pose>0.25 -0.32 0.03 0 0 0</pose>
      <inertial>
        <mass>0.151</mass>
        <inertia>
          <ixx>1.676e-4</ixx>
          <ixy>0</ixy>
          <ixz>0</ixz>
          <iyy>1.663e-4</iyy>
          <iyz>0</iyz>
          <izz>2.620e-4</izz>
        </inertia>
      </inertial>
      <visual name="base_right_front_top_visual">
        <geometry>
          <box>
            <size>0.03 0.25 0.005</size>
          </box>
        </geometry>
        <material>
          <script>
            <name>Gazebo/DarkGrey</name>
            <uri>file://media/materials/scripts/gazebo.material</uri>
          </script>
        </material>
      </visual>
      <collision name="prop_right_front_top_collision">
        <pose>0 0 0 0 0 0</pose>
        <geometry>
          <box>
            <size>0.03 0.25 0.005</size>
          </box>
        </geometry>
        <surface>
          <contact>
            <ode>
              <min_depth>0.001</min_depth>
              <max_vel>0</max_vel>
            </ode>
          </contact>
          <friction>
            <ode/>
          </friction>
        </surface>
      </collision>
    </link>
    <joint name="prop_right_front_top_joint" type="revolute">
      <parent>base_right_front</parent>
      <child>prop_right_front_top</child>
      <axis>
        <xyz>0 0 1</xyz>
        <limit>
          <lower>-1e+16</lower>
          <upper>1e+16</upper>
        </limit>
        <dynamics>
          <spring_reference>0</spring_reference>
          <spring_stiffness>0</spring_stiffness>
        </dynamics>
      </axis>
    </joint>
    <link name="prop_right_front_bottom">
      <pose>0.25 -0.32 -0.03 0 0 0</pose>
      <inertial>
        <mass>0.151</mass>
        <inertia>
          <ixx>1.676e-4</ixx>
          <ixy>0</ixy>
          <ixz>0</ixz>
          <iyy>1.663e-4</iyy>
          <iyz>0</iyz>
          <izz>2.620e-4</izz>
        </inertia>
      </inertial>
      <visual name="base_right_front_bottom_visual">
        <geometry>
          <box>
            <size>0.03 0.25 0.005</size>
          </box>
        </geometry>
        <material>
          <script>
            <name>Gazebo/DarkGrey</name>
            <uri>file://media/materials/scripts/gazebo.material</uri>
          </script>
        </material>
      </visual>
      <collision name="prop_right_front_bottom_collision">
        <pose>0 0 0 0 0 0</pose>
        <geometry>
          <box>
            <size>0.03 0.25 0.005</size>
          </box>
        </geometry>
        <surface>
          <contact>
            <ode>
              <min_depth>0.001</min_depth>
              <max_vel>0</max_vel>
            </ode>
          </contact>
          <friction>
            <ode/>
          </friction>
        </surface>
      </collision>
    </link>
    <joint name="prop_right_front_bottom_joint" type="revolute">
      <parent>base_right_front</parent>
      <child>prop_right_front_bottom</child>
      <axis>
        <xyz>0 0 1</xyz>
        <limit>
          <lower>-1e+16</lower>
          <upper>1e+16</upper>
        </limit>
        <dynamics>
          <spring_reference>0</spring_reference>
          <spring_stiffness>0</spring_stiffness>
        </dynamics>
      </axis>
    </joint>
    <!-- PROPELLERS REAR -->
    <link name="prop_left_rear_top">
      <pose>-0.25 0.32 0.03 0 0 0</pose>
      <inertial>
        <mass>0.151</mass>
        <inertia>
          <ixx>1.676e-4</ixx>
          <ixy>0</ixy>
          <ixz>0</ixz>
          <iyy>1.663e-4</iyy>
          <iyz>0</iyz>
          <izz>2.620e-4</izz>
        </inertia>
      </inertial>
      <visual name="prop_left_rear_top_visual">
        <geometry>
          <box>
            <size>0.03 0.25 0.005</size>
          </box>
        </geometry>
        <material>
          <script>
            <name>Gazebo/DarkGrey</name>
            <uri>file://media/materials/scripts/gazebo.material</uri>
          </script>
        </material>
      </visual>
      <collision name="prop_left_rear_top_collision">
        <pose>0 0 0 0 0 0</pose>
        <geometry>
          <box>
            <size>0.03 0.25 0.005</size>
          </box>
        </geometry>
        <surface>
          <contact>
            <ode>
              <min_depth>0.001</min_depth>
              <max_vel>0</max_vel>
            </ode>
          </contact>
          <friction>
            <ode/>
          </friction>
        </surface>
      </collision>
    </link>
    <joint name="prop_left_rear_top_joint" type="revolute">
      <parent>base_left_rear</parent>
      <child>prop_left_rear_top</child>
      <axis>
        <xyz>0 0 1</xyz>
        <limit>
          <lower>-1e+16</lower>
          <upper>1e+16</upper>
        </limit>
        <dynamics>
          <spring_reference>0</spring_reference>
          <spring_stiffness>0</spring_stiffness>
        </dynamics>
      </axis>
    </joint>
    <link name="prop_left_rear_bottom">
      <pose>-0.25 0.32 -0.03 0 0 0</pose>
      <inertial>
        <mass>0.151</mass>
        <inertia>
          <ixx>1.676e-4</ixx>
          <ixy>0</ixy>
          <ixz>0</ixz>
          <iyy>1.663e-4</iyy>
          <iyz>0</iyz>
          <izz>2.620e-4</izz>
        </inertia>
      </inertial>
      <visual name="base_left_rear_bottom_visual">
        <geometry>
          <box>
            <size>0.03 0.25 0.005</size>
          </box>
        </geometry>
        <material>
          <script>
            <name>Gazebo/DarkGrey</name>
            <uri>file://media/materials/scripts/gazebo.material</uri>
          </script>
        </material>
      </visual>
      <collision name="prop_left_rear_bottom_collision">
        <pose>0 0 0 0 0 0</pose>
        <geometry>
          <box>
            <size>0.03 0.25 0.005</size>
          </box>
        </geometry>
        <surface>
          <contact>
            <ode>
              <min_depth>0.001</min_depth>
              <max_vel>0</max_vel>
            </ode>
          </contact>
          <friction>
            <ode/>
          </friction>
        </surface>
      </collision>
    </link>
    <joint name="prop_left_rear_bottom_joint" type="revolute">
      <parent>base_left_rear</parent>
      <child>prop_left_rear_bottom</child>
      <axis>
        <xyz>0 0 1</xyz>
        <limit>
          <lower>-1e+16</lower>
          <upper>1e+16</upper>
        </limit>
        <dynamics>
          <spring_reference>0</spring_reference>
          <spring_stiffness>0</spring_stiffness>
        </dynamics>
      </axis>
    </joint>
    <!-- RIGHT -->
    <link name="prop_right_rear_top">
      <pose>-0.25 -0.32 0.03 0 0 0</pose>
      <inertial>
        <mass>0.151</mass>
        <inertia>
          <ixx>1.676e-4</ixx>
          <ixy>0</ixy>
          <ixz>0</ixz>
          <iyy>1.663e-4</iyy>
          <iyz>0</iyz>
          <izz>2.620e-4</izz>
        </inertia>
      </inertial>
      <visual name="base_right_rear_top_visual">
        <geometry>
          <box>
            <size>0.03 0.25 0.005</size>
          </box>
        </geometry>
        <material>
          <script>
            <name>Gazebo/DarkGrey</name>
            <uri>file://media/materials/scripts/gazebo.material</uri>
          </script>
        </material>
      </visual>
      <collision name="prop_right_rear_top_collision">
        <pose>0 0 0 0 0 0</pose>
        <geometry>
          <box>
            <size>0.03 0.25 0.005</size>
          </box>
        </geometry>
        <surface>
          <contact>
            <ode>
              <min_depth>0.001</min_depth>
              <max_vel>0</max_vel>
            </ode>
          </contact>
          <friction>
            <ode/>
          </friction>
        </surface>
      </collision>
    </link>
    <joint name="prop_right_rear_top_joint" type="revolute">
      <parent>base_right_rear</parent>
      <child>prop_right_rear_top</child>
      <axis>
        <xyz>0 0 1</xyz>
        <limit>
          <lower>-1e+16</lower>
          <upper>1e+16</upper>
        </limit>
        <dynamics>
          <spring_reference>0</spring_reference>
          <spring_stiffness>0</spring_stiffness>
        </dynamics>
      </axis>
    </joint>
    <link name="prop_right_rear_bottom">
      <pose>-0.25 -0.32 -0.03 0 0 0</pose>
      <inertial>
        <mass>0.151</mass>
        <inertia>
          <ixx>1.676e-4</ixx>
          <ixy>0</ixy>
          <ixz>0</ixz>
          <iyy>1.663e-4</iyy>
          <iyz>0</iyz>
          <izz>2.620e-4</izz>
        </inertia>
      </inertial>
      <visual name="base_right_rear_bottom_visual">
        <geometry>
          <box>
            <size>0.03 0.25 0.005</size>
          </box>
        </geometry>
        <material>
          <script>
            <name>Gazebo/DarkGrey</name>
            <uri>file://media/materials/scripts/gazebo.material</uri>
          </script>
        </material>
      </visual>
      <collision name="prop_right_rear_bottom_collision">
        <pose>0 0 0 0 0 0</pose>
        <geometry>
          <box>
            <size>0.03 0.25 0.005</size>
          </box>
        </geometry>
        <surface>
          <contact>
            <ode>
              <min_depth>0.001</min_depth>
              <max_vel>0</max_vel>
            </ode>
          </contact>
          <friction>
            <ode/>
          </friction>
        </surface>
      </collision>
    </link>
    <joint name="prop_right_rear_bottom_joint" type="revolute">
      <parent>base_right_rear</parent>
      <child>prop_right_rear_bottom</child>
      <axis>
        <xyz>0 0 1</xyz>
        <limit>
          <lower>-1e+16</lower>
          <upper>1e+16</upper>
        </limit>
        <dynamics>
          <spring_reference>0</spring_reference>
          <spring_stiffness>0</spring_stiffness>
        </dynamics>
      </axis>
    </joint>
  <!-- Plug-ins for sim -->
    <plugin name='motor_1_model' filename='libgazebo_motor_model.so'>
      <jointName>prop_left_front_top_joint</jointName>
      <linkName>prop_left_front_top</linkName>
      <turningDirection>cw</turningDirection>
      <timeConstantUp>0.0125</timeConstantUp>
      <timeConstantDown>0.025</timeConstantDown>
      <maxRotVelocity>2000.0</maxRotVelocity>
      <motorConstant>8.54858e-06</motorConstant>
      <momentConstant>0.016</momentConstant>
      <commandSubTopic>/gazebo/command/motor_speed</commandSubTopic>
      <motorNumber>0</motorNumber>
      <rotorDragCoefficient>8.06428e-05</rotorDragCoefficient>
      <rollingMomentCoefficient>1e-06</rollingMomentCoefficient>
      <motorSpeedPubTopic>/motor_speed/0</motorSpeedPubTopic>
      <rotorVelocitySlowdownSim>10</rotorVelocitySlowdownSim>
      <motorType>velocity</motorType>
    </plugin>
    <plugin name='motor_6_model' filename='libgazebo_motor_model.so'>
      <jointName>prop_left_front_bottom_joint</jointName>
      <linkName>prop_left_front_bottom</linkName>
      <turningDirection>ccw</turningDirection>
      <timeConstantUp>0.0125</timeConstantUp>
      <timeConstantDown>0.025</timeConstantDown>
      <maxRotVelocity>2000.0</maxRotVelocity>
      <motorConstant>8.54858e-06</motorConstant>
      <momentConstant>0.016</momentConstant>
      <commandSubTopic>/gazebo/command/motor_speed</commandSubTopic>
      <motorNumber>5</motorNumber>
      <rotorDragCoefficient>8.06428e-05</rotorDragCoefficient>
      <rollingMomentCoefficient>1e-06</rollingMomentCoefficient>
      <motorSpeedPubTopic>/motor_speed/5</motorSpeedPubTopic>
      <rotorVelocitySlowdownSim>10</rotorVelocitySlowdownSim>
      <motorType>velocity</motorType>
    </plugin>
    <plugin name='motor_2_model' filename='libgazebo_motor_model.so'>
      <jointName>prop_right_front_top_joint</jointName>
      <linkName>prop_right_front_top</linkName>
      <turningDirection>ccw</turningDirection>
      <timeConstantUp>0.0125</timeConstantUp>
      <timeConstantDown>0.025</timeConstantDown>
      <maxRotVelocity>2000.0</maxRotVelocity>
      <motorConstant>8.54858e-06</motorConstant>
      <momentConstant>0.016</momentConstant>
      <commandSubTopic>/gazebo/command/motor_speed</commandSubTopic>
      <motorNumber>1</motorNumber>
      <rotorDragCoefficient>8.06428e-05</rotorDragCoefficient>
      <rollingMomentCoefficient>1e-06</rollingMomentCoefficient>
      <motorSpeedPubTopic>/motor_speed/1</motorSpeedPubTopic>
      <rotorVelocitySlowdownSim>10</rotorVelocitySlowdownSim>
      <motorType>velocity</motorType>
    </plugin>
    <plugin name='motor_5_model' filename='libgazebo_motor_model.so'>
      <jointName>prop_right_front_bottom_joint</jointName>
      <linkName>prop_right_front_bottom</linkName>
      <turningDirection>cw</turningDirection>
      <timeConstantUp>0.0125</timeConstantUp>
      <timeConstantDown>0.025</timeConstantDown>
      <maxRotVelocity>2000.0</maxRotVelocity>
      <motorConstant>8.54858e-06</motorConstant>
      <momentConstant>0.016</momentConstant>
      <commandSubTopic>/gazebo/command/motor_speed</commandSubTopic>
      <motorNumber>4</motorNumber>
      <rotorDragCoefficient>8.06428e-05</rotorDragCoefficient>
      <rollingMomentCoefficient>1e-06</rollingMomentCoefficient>
      <motorSpeedPubTopic>/motor_speed/4</motorSpeedPubTopic>
      <rotorVelocitySlowdownSim>10</rotorVelocitySlowdownSim>
      <motorType>velocity</motorType>
    </plugin>
    <plugin name='motor_4_model' filename='libgazebo_motor_model.so'>
      <jointName>prop_left_rear_top_joint</jointName>
      <linkName>prop_left_rear_top</linkName>
      <turningDirection>ccw</turningDirection>
      <timeConstantUp>0.0125</timeConstantUp>
      <timeConstantDown>0.025</timeConstantDown>
      <maxRotVelocity>2000.0</maxRotVelocity>
      <motorConstant>8.54858e-06</motorConstant>
      <momentConstant>0.016</momentConstant>
      <commandSubTopic>/gazebo/command/motor_speed</commandSubTopic>
      <motorNumber>3</motorNumber>
      <rotorDragCoefficient>8.06428e-05</rotorDragCoefficient>
      <rollingMomentCoefficient>1e-06</rollingMomentCoefficient>
      <motorSpeedPubTopic>/motor_speed/3</motorSpeedPubTopic>
      <rotorVelocitySlowdownSim>10</rotorVelocitySlowdownSim>
      <motorType>velocity</motorType>
    </plugin>
    <plugin name='motor_7_model' filename='libgazebo_motor_model.so'>
      <jointName>prop_left_rear_bottom_joint</jointName>
      <linkName>prop_left_rear_bottom</linkName>
      <turningDirection>cw</turningDirection>
      <timeConstantUp>0.0125</timeConstantUp>
      <timeConstantDown>0.025</timeConstantDown>
      <maxRotVelocity>2000.0</maxRotVelocity>
      <motorConstant>8.54858e-06</motorConstant>
      <momentConstant>0.016</momentConstant>
      <commandSubTopic>/gazebo/command/motor_speed</commandSubTopic>
      <motorNumber>6</motorNumber>
      <rotorDragCoefficient>8.06428e-05</rotorDragCoefficient>
      <rollingMomentCoefficient>1e-06</rollingMomentCoefficient>
      <motorSpeedPubTopic>/motor_speed/6</motorSpeedPubTopic>
      <rotorVelocitySlowdownSim>10</rotorVelocitySlowdownSim>
      <motorType>velocity</motorType>
    </plugin>
    <plugin name='motor_3_model' filename='libgazebo_motor_model.so'>
      <jointName>prop_right_rear_top_joint</jointName>
      <linkName>prop_right_rear_top</linkName>
      <turningDirection>cw</turningDirection>
      <timeConstantUp>0.0125</timeConstantUp>
      <timeConstantDown>0.025</timeConstantDown>
      <maxRotVelocity>2000.0</maxRotVelocity>
      <motorConstant>8.54858e-06</motorConstant>
      <momentConstant>0.016</momentConstant>
      <commandSubTopic>/gazebo/command/motor_speed</commandSubTopic>
      <motorNumber>2</motorNumber>
      <rotorDragCoefficient>8.06428e-05</rotorDragCoefficient>
      <rollingMomentCoefficient>1e-06</rollingMomentCoefficient>
      <motorSpeedPubTopic>/motor_speed/2</motorSpeedPubTopic>
      <rotorVelocitySlowdownSim>10</rotorVelocitySlowdownSim>
      <motorType>velocity</motorType>
    </plugin>
    <plugin name='motor_8_model' filename='libgazebo_motor_model.so'>
      <jointName>prop_right_rear_bottom_joint</jointName>
      <linkName>prop_right_rear_bottom</linkName>
      <turningDirection>ccw</turningDirection>
      <timeConstantUp>0.0125</timeConstantUp>
      <timeConstantDown>0.025</timeConstantDown>
      <maxRotVelocity>2000.0</maxRotVelocity>
      <motorConstant>8.54858e-06</motorConstant>
      <momentConstant>0.016</momentConstant>
      <commandSubTopic>/gazebo/command/motor_speed</commandSubTopic>
      <motorNumber>7</motorNumber>
      <rotorDragCoefficient>8.06428e-05</rotorDragCoefficient>
      <rollingMomentCoefficient>1e-06</rollingMomentCoefficient>
      <motorSpeedPubTopic>/motor_speed/7</motorSpeedPubTopic>
      <rotorVelocitySlowdownSim>10</rotorVelocitySlowdownSim>
      <motorType>velocity</motorType>
    </plugin>
    <include>
      <uri>model://gps</uri>
      <pose>0.1 0 0 0 0 0</pose>
      <name>gps0</name>
    </include>
    <joint name='gps0_joint' type='fixed'>
      <child>gps0::link</child>
      <parent>base_link</parent>
    </joint>
    <include>
      <uri>model://magnetometer</uri>
      <pose>0 0 0 0 0 0</pose>
      <name>mag</name>
    </include>
    <joint name='mag_joint' type='fixed'>
      <child>mag::link</child>
      <parent>base_link</parent>
    </joint>
    <plugin name='groundtruth_plugin' filename='libgazebo_groundtruth_plugin.so'>
      <robotNamespace/>
    </plugin>
    <plugin name='barometer_plugin' filename='libgazebo_barometer_plugin.so'>
      <robotNamespace/>
      <pubRate>50</pubRate>
      <baroTopic>/baro</baroTopic>
      <baroDriftPaPerSec>0</baroDriftPaPerSec>
    </plugin>
    <plugin name='mavlink_interface' filename='libgazebo_mavlink_interface.so'>
      <robotNamespace/>
      <imuSubTopic>/imu</imuSubTopic>
      <magSubTopic>/mag</magSubTopic>
      <baroSubTopic>/baro</baroSubTopic>
      <mavlink_addr>INADDR_ANY</mavlink_addr>
      <mavlink_tcp_port>{{ mavlink_tcp_port }}</mavlink_tcp_port>
      <mavlink_udp_port>{{ mavlink_udp_port }}</mavlink_udp_port>
      <serialEnabled>{{ serial_enabled }}</serialEnabled>
      <serialDevice>{{ serial_device }}</serialDevice>
      <baudRate>{{ serial_baudrate }}</baudRate>
      <qgc_addr>INADDR_ANY</qgc_addr>
      <qgc_udp_port>14550</qgc_udp_port>
      <sdk_addr>INADDR_ANY</sdk_addr>
      <sdk_udp_port>14540</sdk_udp_port>
      <hil_mode>{{ hil_mode }}</hil_mode>
      <hil_state_level>0</hil_state_level>
      <send_vision_estimation>0</send_vision_estimation>
      <send_odometry>1</send_odometry>
      <enable_lockstep>1</enable_lockstep>
      <use_tcp>1</use_tcp>
      <motorSpeedCommandPubTopic>/gazebo/command/motor_speed</motorSpeedCommandPubTopic>
      <control_channels>
        <channel name='rotor1'>
          <input_index>0</input_index>
          <input_offset>0</input_offset>
          <input_scaling>1000</input_scaling>
          <zero_position_disarmed>0</zero_position_disarmed>
          <zero_position_armed>100</zero_position_armed>
          <joint_control_type>velocity</joint_control_type>
        </channel>
        <channel name='rotor2'>
          <input_index>1</input_index>
          <input_offset>0</input_offset>
          <input_scaling>1000</input_scaling>
          <zero_position_disarmed>0</zero_position_disarmed>
          <zero_position_armed>100</zero_position_armed>
          <joint_control_type>velocity</joint_control_type>
        </channel>
        <channel name='rotor3'>
          <input_index>2</input_index>
          <input_offset>0</input_offset>
          <input_scaling>1000</input_scaling>
          <zero_position_disarmed>0</zero_position_disarmed>
          <zero_position_armed>100</zero_position_armed>
          <joint_control_type>velocity</joint_control_type>
        </channel>
        <channel name='rotor4'>
          <input_index>3</input_index>
          <input_offset>0</input_offset>
          <input_scaling>1000</input_scaling>
          <zero_position_disarmed>0</zero_position_disarmed>
          <zero_position_armed>100</zero_position_armed>
          <joint_control_type>velocity</joint_control_type>
        </channel>
        <channel name='rotor5'>
          <input_index>4</input_index>
          <input_offset>0</input_offset>
          <input_scaling>1000</input_scaling>
          <zero_position_disarmed>0</zero_position_disarmed>
          <zero_position_armed>100</zero_position_armed>
          <joint_control_type>velocity</joint_control_type>
        </channel>
        <channel name='rotor6'>
          <input_index>5</input_index>
          <input_offset>0</input_offset>
          <input_scaling>1000</input_scaling>
          <zero_position_disarmed>0</zero_position_disarmed>
          <zero_position_armed>100</zero_position_armed>
          <joint_control_type>velocity</joint_control_type>
        </channel>
        <channel name='rotor7'>
          <input_index>6</input_index>
          <input_offset>0</input_offset>
          <input_scaling>1000</input_scaling>
          <zero_position_disarmed>0</zero_position_disarmed>
          <zero_position_armed>100</zero_position_armed>
          <joint_control_type>velocity</joint_control_type>
        </channel>
        <channel name='rotor8'>
          <input_index>7</input_index>
          <input_offset>0</input_offset>
          <input_scaling>1000</input_scaling>
          <zero_position_disarmed>0</zero_position_disarmed>
          <zero_position_armed>100</zero_position_armed>
          <joint_control_type>velocity</joint_control_type>
        </channel>

        <channel name="motor_tilt_arm_bwd">
          <input_index>8</input_index>
          <input_offset>0.0</input_offset>
          <input_scaling>-1.57</input_scaling>
          <zero_position_disarmed>0</zero_position_disarmed>
          <zero_position_armed>0</zero_position_armed>
          <joint_control_type>position</joint_control_type>
          <joint_name>base_right_front_joint</joint_name>
           <joint_control_pid>
            <p>200</p>
            <i>0</i>
            <d>1</d>
            <iMax>0.0</iMax>
            <iMin>0.0</iMin>
            <cmdMax>2</cmdMax>
            <cmdMin>-2</cmdMin>
          </joint_control_pid>
        </channel>
        <channel name="motor_tilt_arm_bwd_left">
          <input_index>9</input_index>
          <input_offset>0.0</input_offset>
          <input_scaling>-1.57</input_scaling>
          <zero_position_disarmed>0</zero_position_disarmed>
          <zero_position_armed>0</zero_position_armed>
          <joint_control_type>position</joint_control_type>
          <joint_name>base_left_front_joint</joint_name>
           <joint_control_pid>
            <p>200</p>
            <i>0</i>
            <d>1</d>
            <iMax>0.0</iMax>
            <iMin>0.0</iMin>
            <cmdMax>2</cmdMax>
            <cmdMin>-2</cmdMin>
          </joint_control_pid>
        </channel>
        <channel name='motor_tilt_arm_fwd'>
          <input_index>10</input_index>
          <input_offset>0.0</input_offset>
          <input_scaling>-1.57</input_scaling>
          <zero_position_disarmed>0</zero_position_disarmed>
          <zero_position_armed>0</zero_position_armed>
          <joint_control_type>position</joint_control_type>
          <joint_name>base_right_rear_joint</joint_name>
          <joint_control_pid>
            <p>200.0</p>
            <i>0</i>
            <d>1</d>
            <iMax>0</iMax>
            <iMin>0</iMin>
            <cmdMax>2</cmdMax>
            <cmdMin>-2</cmdMin>
          </joint_control_pid>
        </channel>
        <channel name='motor_tilt_arm_fwd_left'>
          <input_index>11</input_index>
          <input_offset>0.0</input_offset>
          <input_scaling>-1.57</input_scaling>
          <zero_position_disarmed>0</zero_position_disarmed>
          <zero_position_armed>0</zero_position_armed>
          <joint_control_type>position</joint_control_type>
          <joint_name>base_left_rear_joint</joint_name>
          <joint_control_pid>
            <p>200.0</p>
            <i>0</i>
            <d>1</d>
            <iMax>0</iMax>
            <iMin>0</iMin>
            <cmdMax>2</cmdMax>
            <cmdMin>-2</cmdMin>
          </joint_control_pid>
        </channel>

      </control_channels>
    </plugin>
    <static>0</static>
  </model>
</sdf>

